2020-10-28 12:04:51,381 ERROR: Exception on /start_test [GET] [in c:\users\44792\appdata\local\programs\python\python38\lib\site-packages\flask\app.py:1891]
Traceback (most recent call last):
  File "c:\users\44792\appdata\local\programs\python\python38\lib\site-packages\flask\app.py", line 2447, in wsgi_app
    response = self.full_dispatch_request()
  File "c:\users\44792\appdata\local\programs\python\python38\lib\site-packages\flask\app.py", line 1952, in full_dispatch_request
    rv = self.handle_user_exception(e)
  File "c:\users\44792\appdata\local\programs\python\python38\lib\site-packages\flask\app.py", line 1821, in handle_user_exception
    reraise(exc_type, exc_value, tb)
  File "c:\users\44792\appdata\local\programs\python\python38\lib\site-packages\flask\_compat.py", line 39, in reraise
    raise value
  File "c:\users\44792\appdata\local\programs\python\python38\lib\site-packages\flask\app.py", line 1950, in full_dispatch_request
    rv = self.dispatch_request()
  File "c:\users\44792\appdata\local\programs\python\python38\lib\site-packages\flask\app.py", line 1936, in dispatch_request
    return self.view_functions[rule.endpoint](**req.view_args)
  File "c:\users\44792\appdata\local\programs\python\python38\lib\site-packages\flask_login\utils.py", line 272, in decorated_view
    return func(*args, **kwargs)
  File "C:\Users\44792\Documents\PythonProjects\AdaptiveMath\web\app\main\routes.py", line 153, in start_test
    session['questionstarttime'] = json.dump(qStartDict)
TypeError: dump() missing 1 required positional argument: 'fp'
2020-10-28 12:05:35,556 INFO: create_app started. [in C:\Users\44792\Documents\PythonProjects\AdaptiveMath\web\app\__init__.py:51]
2020-10-28 12:05:37,601 INFO: start_test GET [in C:\Users\44792\Documents\PythonProjects\AdaptiveMath\web\app\main\routes.py:95]
2020-10-28 12:05:37,606 INFO: load question 184: 9 + 3 = at 2020-10-28 12:05:37.606497  [in C:\Users\44792\Documents\PythonProjects\AdaptiveMath\web\app\main\routes.py:145]
2020-10-28 12:05:37,606 INFO: session["questionstarttime"] {}  [in C:\Users\44792\Documents\PythonProjects\AdaptiveMath\web\app\main\routes.py:148]
2020-10-28 12:05:37,607 ERROR: Exception on /start_test [GET] [in c:\users\44792\appdata\local\programs\python\python38\lib\site-packages\flask\app.py:1891]
Traceback (most recent call last):
  File "c:\users\44792\appdata\local\programs\python\python38\lib\site-packages\flask\app.py", line 2447, in wsgi_app
    response = self.full_dispatch_request()
  File "c:\users\44792\appdata\local\programs\python\python38\lib\site-packages\flask\app.py", line 1952, in full_dispatch_request
    rv = self.handle_user_exception(e)
  File "c:\users\44792\appdata\local\programs\python\python38\lib\site-packages\flask\app.py", line 1821, in handle_user_exception
    reraise(exc_type, exc_value, tb)
  File "c:\users\44792\appdata\local\programs\python\python38\lib\site-packages\flask\_compat.py", line 39, in reraise
    raise value
  File "c:\users\44792\appdata\local\programs\python\python38\lib\site-packages\flask\app.py", line 1950, in full_dispatch_request
    rv = self.dispatch_request()
  File "c:\users\44792\appdata\local\programs\python\python38\lib\site-packages\flask\app.py", line 1936, in dispatch_request
    return self.view_functions[rule.endpoint](**req.view_args)
  File "c:\users\44792\appdata\local\programs\python\python38\lib\site-packages\flask_login\utils.py", line 272, in decorated_view
    return func(*args, **kwargs)
  File "C:\Users\44792\Documents\PythonProjects\AdaptiveMath\web\app\main\routes.py", line 153, in start_test
    session['questionstarttime'] = json.dumps(qStartDict)
  File "c:\users\44792\appdata\local\programs\python\python38\lib\json\__init__.py", line 231, in dumps
    return _default_encoder.encode(obj)
  File "c:\users\44792\appdata\local\programs\python\python38\lib\json\encoder.py", line 199, in encode
    chunks = self.iterencode(o, _one_shot=True)
  File "c:\users\44792\appdata\local\programs\python\python38\lib\json\encoder.py", line 257, in iterencode
    return _iterencode(o, 0)
  File "c:\users\44792\appdata\local\programs\python\python38\lib\json\encoder.py", line 179, in default
    raise TypeError(f'Object of type {o.__class__.__name__} '
TypeError: Object of type datetime is not JSON serializable
2020-10-28 12:06:08,480 INFO: create_app started. [in C:\Users\44792\Documents\PythonProjects\AdaptiveMath\web\app\__init__.py:51]
2020-10-28 12:06:13,420 INFO: start_test GET [in C:\Users\44792\Documents\PythonProjects\AdaptiveMath\web\app\main\routes.py:95]
2020-10-28 12:06:13,421 INFO: load question 184: 9 + 3 = at 2020-10-28 12:06:13.421032  [in C:\Users\44792\Documents\PythonProjects\AdaptiveMath\web\app\main\routes.py:145]
2020-10-28 12:06:13,422 INFO: session["questionstarttime"] {}  [in C:\Users\44792\Documents\PythonProjects\AdaptiveMath\web\app\main\routes.py:148]
2020-10-28 12:06:13,429 INFO: qStartDict {184: datetime.datetime(2020, 10, 28, 12, 6, 13, 429013)} saved to session [in C:\Users\44792\Documents\PythonProjects\AdaptiveMath\web\app\main\routes.py:154]
2020-10-28 12:07:11,217 INFO: start_test POST [in C:\Users\44792\Documents\PythonProjects\AdaptiveMath\web\app\main\routes.py:95]
2020-10-28 12:07:11,220 INFO: load question 184: 9 + 3 = at 2020-10-28 12:07:11.220586  [in C:\Users\44792\Documents\PythonProjects\AdaptiveMath\web\app\main\routes.py:145]
2020-10-28 12:07:11,227 INFO: session["questionstarttime"] {'184': datetime.datetime(2020, 10, 28, 12, 6, 13)}  [in C:\Users\44792\Documents\PythonProjects\AdaptiveMath\web\app\main\routes.py:148]
2020-10-28 12:07:11,228 INFO: qStartDict {'184': datetime.datetime(2020, 10, 28, 12, 6, 13), 184: datetime.datetime(2020, 10, 28, 12, 7, 11, 228502)} saved to session [in C:\Users\44792\Documents\PythonProjects\AdaptiveMath\web\app\main\routes.py:154]
2020-10-28 12:07:11,229 INFO: question 184 start 2020-10-28 12:07:11.228502 end time 2020-10-28 12:07:11.229499. [in C:\Users\44792\Documents\PythonProjects\AdaptiveMath\web\app\main\routes.py:174]
2020-10-28 12:07:11,306 ERROR: Exception on /start_test [POST] [in c:\users\44792\appdata\local\programs\python\python38\lib\site-packages\flask\app.py:1891]
Traceback (most recent call last):
  File "c:\users\44792\appdata\local\programs\python\python38\lib\site-packages\flask\app.py", line 2447, in wsgi_app
    response = self.full_dispatch_request()
  File "c:\users\44792\appdata\local\programs\python\python38\lib\site-packages\flask\app.py", line 1953, in full_dispatch_request
    return self.finalize_request(rv)
  File "c:\users\44792\appdata\local\programs\python\python38\lib\site-packages\flask\app.py", line 1970, in finalize_request
    response = self.process_response(response)
  File "c:\users\44792\appdata\local\programs\python\python38\lib\site-packages\flask\app.py", line 2269, in process_response
    self.session_interface.save_session(self, ctx.session, response)
  File "c:\users\44792\appdata\local\programs\python\python38\lib\site-packages\flask\sessions.py", line 378, in save_session
    val = self.get_signing_serializer(app).dumps(dict(session))
  File "c:\users\44792\appdata\local\programs\python\python38\lib\site-packages\itsdangerous\serializer.py", line 166, in dumps
    payload = want_bytes(self.dump_payload(obj))
  File "c:\users\44792\appdata\local\programs\python\python38\lib\site-packages\itsdangerous\url_safe.py", line 42, in dump_payload
    json = super(URLSafeSerializerMixin, self).dump_payload(obj)
  File "c:\users\44792\appdata\local\programs\python\python38\lib\site-packages\itsdangerous\serializer.py", line 133, in dump_payload
    return want_bytes(self.serializer.dumps(obj, **self.serializer_kwargs))
  File "c:\users\44792\appdata\local\programs\python\python38\lib\site-packages\flask\json\tag.py", line 305, in dumps
    return dumps(self.tag(value), separators=(",", ":"))
  File "c:\users\44792\appdata\local\programs\python\python38\lib\site-packages\flask\json\__init__.py", line 211, in dumps
    rv = _json.dumps(obj, **kwargs)
  File "c:\users\44792\appdata\local\programs\python\python38\lib\json\__init__.py", line 234, in dumps
    return cls(
  File "c:\users\44792\appdata\local\programs\python\python38\lib\json\encoder.py", line 199, in encode
    chunks = self.iterencode(o, _one_shot=True)
  File "c:\users\44792\appdata\local\programs\python\python38\lib\json\encoder.py", line 257, in iterencode
    return _iterencode(o, 0)
TypeError: '<' not supported between instances of 'int' and 'str'
