2020-10-28 12:07:11,321 ERROR: Request finalizing failed with an error while handling an error [in c:\users\44792\appdata\local\programs\python\python38\lib\site-packages\flask\app.py:1975]
Traceback (most recent call last):
  File "c:\users\44792\appdata\local\programs\python\python38\lib\site-packages\flask\app.py", line 2447, in wsgi_app
    response = self.full_dispatch_request()
  File "c:\users\44792\appdata\local\programs\python\python38\lib\site-packages\flask\app.py", line 1953, in full_dispatch_request
    return self.finalize_request(rv)
  File "c:\users\44792\appdata\local\programs\python\python38\lib\site-packages\flask\app.py", line 1970, in finalize_request
    response = self.process_response(response)
  File "c:\users\44792\appdata\local\programs\python\python38\lib\site-packages\flask\app.py", line 2269, in process_response
    self.session_interface.save_session(self, ctx.session, response)
  File "c:\users\44792\appdata\local\programs\python\python38\lib\site-packages\flask\sessions.py", line 378, in save_session
    val = self.get_signing_serializer(app).dumps(dict(session))
  File "c:\users\44792\appdata\local\programs\python\python38\lib\site-packages\itsdangerous\serializer.py", line 166, in dumps
    payload = want_bytes(self.dump_payload(obj))
  File "c:\users\44792\appdata\local\programs\python\python38\lib\site-packages\itsdangerous\url_safe.py", line 42, in dump_payload
    json = super(URLSafeSerializerMixin, self).dump_payload(obj)
  File "c:\users\44792\appdata\local\programs\python\python38\lib\site-packages\itsdangerous\serializer.py", line 133, in dump_payload
    return want_bytes(self.serializer.dumps(obj, **self.serializer_kwargs))
  File "c:\users\44792\appdata\local\programs\python\python38\lib\site-packages\flask\json\tag.py", line 305, in dumps
    return dumps(self.tag(value), separators=(",", ":"))
  File "c:\users\44792\appdata\local\programs\python\python38\lib\site-packages\flask\json\__init__.py", line 211, in dumps
    rv = _json.dumps(obj, **kwargs)
  File "c:\users\44792\appdata\local\programs\python\python38\lib\json\__init__.py", line 234, in dumps
    return cls(
  File "c:\users\44792\appdata\local\programs\python\python38\lib\json\encoder.py", line 199, in encode
    chunks = self.iterencode(o, _one_shot=True)
  File "c:\users\44792\appdata\local\programs\python\python38\lib\json\encoder.py", line 257, in iterencode
    return _iterencode(o, 0)
TypeError: '<' not supported between instances of 'int' and 'str'

During handling of the above exception, another exception occurred:

Traceback (most recent call last):
  File "c:\users\44792\appdata\local\programs\python\python38\lib\site-packages\flask\app.py", line 1970, in finalize_request
    response = self.process_response(response)
  File "c:\users\44792\appdata\local\programs\python\python38\lib\site-packages\flask\app.py", line 2269, in process_response
    self.session_interface.save_session(self, ctx.session, response)
  File "c:\users\44792\appdata\local\programs\python\python38\lib\site-packages\flask\sessions.py", line 378, in save_session
    val = self.get_signing_serializer(app).dumps(dict(session))
  File "c:\users\44792\appdata\local\programs\python\python38\lib\site-packages\itsdangerous\serializer.py", line 166, in dumps
    payload = want_bytes(self.dump_payload(obj))
  File "c:\users\44792\appdata\local\programs\python\python38\lib\site-packages\itsdangerous\url_safe.py", line 42, in dump_payload
    json = super(URLSafeSerializerMixin, self).dump_payload(obj)
  File "c:\users\44792\appdata\local\programs\python\python38\lib\site-packages\itsdangerous\serializer.py", line 133, in dump_payload
    return want_bytes(self.serializer.dumps(obj, **self.serializer_kwargs))
  File "c:\users\44792\appdata\local\programs\python\python38\lib\site-packages\flask\json\tag.py", line 305, in dumps
    return dumps(self.tag(value), separators=(",", ":"))
  File "c:\users\44792\appdata\local\programs\python\python38\lib\site-packages\flask\json\__init__.py", line 211, in dumps
    rv = _json.dumps(obj, **kwargs)
  File "c:\users\44792\appdata\local\programs\python\python38\lib\json\__init__.py", line 234, in dumps
    return cls(
  File "c:\users\44792\appdata\local\programs\python\python38\lib\json\encoder.py", line 199, in encode
    chunks = self.iterencode(o, _one_shot=True)
  File "c:\users\44792\appdata\local\programs\python\python38\lib\json\encoder.py", line 257, in iterencode
    return _iterencode(o, 0)
TypeError: '<' not supported between instances of 'int' and 'str'
2020-10-29 09:22:37,372 INFO: create_app started. [in C:\Users\44792\Documents\PythonProjects\AdaptiveMath\web\app\__init__.py:51]
2020-10-29 09:41:13,211 INFO: create_app started. [in C:\Users\44792\Documents\PythonProjects\AdaptiveMath\web\app\__init__.py:51]
2020-10-29 09:41:46,243 INFO: question 48 start 2020-10-29 09:41:46.243234 end time 2020-10-29 09:41:46.243234. [in C:\Users\44792\Documents\PythonProjects\AdaptiveMath\web\app\main\routes.py:126]
2020-10-29 09:41:46,244 ERROR: Exception on /start_practice [POST] [in c:\users\44792\appdata\local\programs\python\python38\lib\site-packages\flask\app.py:1891]
Traceback (most recent call last):
  File "c:\users\44792\appdata\local\programs\python\python38\lib\site-packages\flask\app.py", line 2447, in wsgi_app
    response = self.full_dispatch_request()
  File "c:\users\44792\appdata\local\programs\python\python38\lib\site-packages\flask\app.py", line 1952, in full_dispatch_request
    rv = self.handle_user_exception(e)
  File "c:\users\44792\appdata\local\programs\python\python38\lib\site-packages\flask\app.py", line 1821, in handle_user_exception
    reraise(exc_type, exc_value, tb)
  File "c:\users\44792\appdata\local\programs\python\python38\lib\site-packages\flask\_compat.py", line 39, in reraise
    raise value
  File "c:\users\44792\appdata\local\programs\python\python38\lib\site-packages\flask\app.py", line 1950, in full_dispatch_request
    rv = self.dispatch_request()
  File "c:\users\44792\appdata\local\programs\python\python38\lib\site-packages\flask\app.py", line 1936, in dispatch_request
    return self.view_functions[rule.endpoint](**req.view_args)
  File "c:\users\44792\appdata\local\programs\python\python38\lib\site-packages\flask_login\utils.py", line 272, in decorated_view
    return func(*args, **kwargs)
  File "C:\Users\44792\Documents\PythonProjects\AdaptiveMath\web\app\main\routes.py", line 127, in start_practice
    record = Record(userid=int(session['userid']),testid=int(session['testid']),questionid=int(form.qid.data),datecreated=datetime.now(),result=result,timetaken = sectaken,response = form.response.data)
  File "c:\users\44792\appdata\local\programs\python\python38\lib\site-packages\werkzeug\local.py", line 377, in <lambda>
    __getitem__ = lambda x, i: x._get_current_object()[i]
  File "c:\users\44792\appdata\local\programs\python\python38\lib\site-packages\flask\sessions.py", line 84, in __getitem__
    return super(SecureCookieSession, self).__getitem__(key)
KeyError: 'testid'
2020-10-29 09:44:12,974 INFO: create_app started. [in C:\Users\44792\Documents\PythonProjects\AdaptiveMath\web\app\__init__.py:51]
2020-10-29 09:44:17,895 INFO: question 13 start 2020-10-29 09:44:17.895309 end time 2020-10-29 09:44:17.895309. [in C:\Users\44792\Documents\PythonProjects\AdaptiveMath\web\app\main\routes.py:126]
2020-10-29 09:44:20,635 INFO: question 17 start 2020-10-29 09:44:20.635394 end time 2020-10-29 09:44:20.635394. [in C:\Users\44792\Documents\PythonProjects\AdaptiveMath\web\app\main\routes.py:126]
2020-10-29 09:44:25,238 INFO: question 115 start 2020-10-29 09:44:25.238315 end time 2020-10-29 09:44:25.238315. [in C:\Users\44792\Documents\PythonProjects\AdaptiveMath\web\app\main\routes.py:126]
2020-10-29 09:44:27,842 INFO: question 266 start 2020-10-29 09:44:27.842847 end time 2020-10-29 09:44:27.842847. [in C:\Users\44792\Documents\PythonProjects\AdaptiveMath\web\app\main\routes.py:126]
2020-10-29 09:44:30,472 INFO: question 256 start 2020-10-29 09:44:30.472413 end time 2020-10-29 09:44:30.472413. [in C:\Users\44792\Documents\PythonProjects\AdaptiveMath\web\app\main\routes.py:126]
2020-10-29 09:44:33,305 INFO: question 174 start 2020-10-29 09:44:33.305781 end time 2020-10-29 09:44:33.305781. [in C:\Users\44792\Documents\PythonProjects\AdaptiveMath\web\app\main\routes.py:126]
2020-10-29 09:44:38,869 INFO: question 75 start 2020-10-29 09:44:38.869390 end time 2020-10-29 09:44:38.869390. [in C:\Users\44792\Documents\PythonProjects\AdaptiveMath\web\app\main\routes.py:126]
2020-10-29 09:44:41,114 INFO: question 231 start 2020-10-29 09:44:41.114373 end time 2020-10-29 09:44:41.114373. [in C:\Users\44792\Documents\PythonProjects\AdaptiveMath\web\app\main\routes.py:126]
2020-10-29 09:44:44,613 INFO: question 306 start 2020-10-29 09:44:44.613986 end time 2020-10-29 09:44:44.613986. [in C:\Users\44792\Documents\PythonProjects\AdaptiveMath\web\app\main\routes.py:126]
2020-10-29 09:44:49,943 INFO: question 277 start 2020-10-29 09:44:49.943430 end time 2020-10-29 09:44:49.943430. [in C:\Users\44792\Documents\PythonProjects\AdaptiveMath\web\app\main\routes.py:126]
2020-10-29 09:46:29,384 INFO: question 313 start 2020-10-29 09:46:29.384409 end time 2020-10-29 09:46:29.384409. [in C:\Users\44792\Documents\PythonProjects\AdaptiveMath\web\app\main\routes.py:126]
